Workbook

Sheet Sheet1
A1: 공 종 | B1: 도면번호 | C1: 기둥번호 | D1: 규 격 | E1: 길 이(mm) | F1: 중 량(kg) | G1: 운송차수계획(13차) | H1: 조정된 차수계획(12차)
A2: =[1]추출용DB!B5 -> K.COLUMN | B2: =[1]추출용DB!C5 -> 1C001 | D2: =[1]추출용DB!D5 -> H506*201*11*19 | E2: =[1]추출용DB!E5 -> 15300 | F2: =[1]추출용DB!G5 -> 3565.2
A3: =[1]추출용DB!B6 -> K.COLUMN | B3: =[1]추출용DB!C6 -> 1C002 | D3: =[1]추출용DB!D6 -> H506*201*11*19 | E3: =[1]추출용DB!E6 -> 12794 | F3: =[1]추출용DB!G6 -> 3367.7
A4: =[1]추출용DB!B7 -> K.COLUMN | B4: =[1]추출용DB!C7 -> 2C001 | D4: =[1]추출용DB!D7 -> H500*200*10*16 | E4: =[1]추출용DB!E7 -> 12800 | F4: =[1]추출용DB!G7 -> 2724.6
A5: =[1]추출용DB!B8 -> K.COLUMN | B5: =[1]추출용DB!C8 -> 2C002 | D5: =[1]추출용DB!D8 -> H500*200*10*16 | E5: =[1]추출용DB!E8 -> 12794 | F5: =[1]추출용DB!G8 -> 3123.6
A6: =[1]추출용DB!B9 -> K.COLUMN | B6: =[1]추출용DB!C9 -> 3C001 | D6: =[1]추출용DB!D9 -> H500*200*10*16 | E6: =[1]추출용DB!E9 -> 12000 | F6: =[1]추출용DB!G9 -> 2600
A7: =[1]추출용DB!B10 -> K.COLUMN | B7: =[1]추출용DB!C10 -> 3C002 | D7: =[1]추출용DB!D10 -> H500*200*10*16 | E7: =[1]추출용DB!E10 -> 11994 | F7: =[1]추출용DB!G10 -> 2828.6
A8: =[1]추출용DB!B11 -> K.COLUMN | B8: =[1]추출용DB!C11 -> 4C001 | D8: =[1]추출용DB!D11 -> H500*200*10*16 | E8: =[1]추출용DB!E11 -> 13500 | F8: =[1]추출용DB!G11 -> 2908.4
A9: =[1]추출용DB!B12 -> K.COLUMN | B9: =[1]추출용DB!C12 -> 4C002 | D9: =[1]추출용DB!D12 -> H500*200*10*16 | E9: =[1]추출용DB!E12 -> 11994 | F9: =[1]추출용DB!G12 -> 2828.6
A10: =[1]추출용DB!B23 -> K.COLUMN | B10: =[1]추출용DB!C23 -> 10C001 | D10: =[1]추출용DB!D23 -> H506*201*11*19 | E10: =[1]추출용DB!E23 -> 12800 | F10: =[1]추출용DB!G23 -> 2991.2
A11: =[1]추출용DB!B24 -> K.COLUMN | B11: =[1]추출용DB!C24 -> 10C002 | D11: =[1]추출용DB!D24 -> H506*201*11*19 | E11: =[1]추출용DB!E24 -> 12794 | F11: =[1]추출용DB!G24 -> 3351.4
A12: =[1]추출용DB!B25 -> K.COLUMN | B12: =[1]추출용DB!C25 -> 11C001 | D12: =[1]추출용DB!D25 -> H506*201*11*19 | E12: =[1]추출용DB!E25 -> 12800 | F12: =[1]추출용DB!G25 -> 2991.2
A13: =[1]추출용DB!B26 -> K.COLUMN | B13: =[1]추출용DB!C26 -> 11C002 | D13: =[1]추출용DB!D26 -> H506*201*11*19 | E13: =[1]추출용DB!E26 -> 12794 | F13: =[1]추출용DB!G26 -> 3320.3
A14: =[1]추출용DB!B27 -> K.COLUMN | B14: =[1]추출용DB!C27 -> 12C001 | D14: =[1]추출용DB!D27 -> H500*200*10*16 | E14: =[1]추출용DB!E27 -> 12800 | F14: =[1]추출용DB!G27 -> 2676.3
A15: =[1]추출용DB!B28 -> K.COLUMN | B15: =[1]추출용DB!C28 -> 12C002 | D15: =[1]추출용DB!D28 -> H500*200*10*16 | E15: =[1]추출용DB!E28 -> 12794 | F15: =[1]추출용DB!G28 -> 3052.9
A16: =[1]추출용DB!B13 -> K.COLUMN | B16: =[1]추출용DB!C13 -> 5C001 | D16: =[1]추출용DB!D13 -> H500*200*10*16 | E16: =[1]추출용DB!E13 -> 12800 | F16: =[1]추출용DB!G13 -> 2569.5
A17: =[1]추출용DB!B14 -> K.COLUMN | B17: =[1]추출용DB!C14 -> 5C002 | D17: =[1]추출용DB!D14 -> H500*200*10*16 | E17: =[1]추출용DB!E14 -> 11994 | F17: =[1]추출용DB!G14 -> 2828.6
A18: =[1]추출용DB!B41 -> K.COLUMN | B18: =[1]추출용DB!C41 -> 19C001 | D18: =[1]추출용DB!D41 -> H500*200*10*16 | E18: =[1]추출용DB!E41 -> 12800 | F18: =[1]추출용DB!G41 -> 2569.5
A19: =[1]추출용DB!B42 -> K.COLUMN | B19: =[1]추출용DB!C42 -> 19C002 | D19: =[1]추출용DB!D42 -> H500*200*10*16 | E19: =[1]추출용DB!E42 -> 11994 | F19: =[1]추출용DB!G42 -> 2828.6
A20: =[1]추출용DB!B43 -> K.COLUMN | B20: =[1]추출용DB!C43 -> 20C001 | D20: =[1]추출용DB!D43 -> H500*200*10*16 | E20: =[1]추출용DB!E43 -> 11500 | F20: =[1]추출용DB!G43 -> 2340.2
A21: =[1]추출용DB!B44 -> K.COLUMN | B21: =[1]추출용DB!C44 -> 20C002 | D21: =[1]추출용DB!D44 -> H500*200*10*16 | E21: =[1]추출용DB!E44 -> 11994 | F21: =[1]추출용DB!G44 -> 2828.6
A22: =[1]추출용DB!B15 -> K.COLUMN | B22: =[1]추출용DB!C15 -> 6C001 | D22: =[1]추출용DB!D15 -> H506*201*11*19 | E22: =[1]추출용DB!E15 -> 12800 | F22: =[1]추출용DB!G15 -> 2903.4
A23: =[1]추출용DB!B16 -> K.COLUMN | B23: =[1]추출용DB!C16 -> 6C002 | D23: =[1]추출용DB!D16 -> H506*201*11*19 | E23: =[1]추출용DB!E16 -> 11994 | F23: =[1]추출용DB!G16 -> 3151.3
A24: =[1]추출용DB!B17 -> T.COLUMN | B24: =[1]추출용DB!C17 -> 7TC001 | D24: =[1]추출용DB!D17 -> H450*200*9*14 | E24: =[1]추출용DB!E17 -> 12800 | F24: =[1]추출용DB!G17 -> 2152.6
A25: =[1]추출용DB!B18 -> T.COLUMN | B25: =[1]추출용DB!C18 -> 7TC002 | D25: =[1]추출용DB!D18 -> H450*200*9*14 | E25: =[1]추출용DB!E18 -> 12794 | F25: =[1]추출용DB!G18 -> 2473
A26: =[1]추출용DB!B19 -> T.COLUMN | B26: =[1]추출용DB!C19 -> 8TC001 | D26: =[1]추출용DB!D19 -> H450*200*9*14 | E26: =[1]추출용DB!E19 -> 14200 | F26: =[1]추출용DB!G19 -> 2433
A27: =[1]추출용DB!B20 -> T.COLUMN | B27: =[1]추출용DB!C20 -> 8TC002 | D27: =[1]추출용DB!D20 -> H450*200*9*14 | E27: =[1]추출용DB!E20 -> 12794 | F27: =[1]추출용DB!G20 -> 2679
A28: =[1]추출용DB!B21 -> K.COLUMN | B28: =[1]추출용DB!C21 -> 9C001 | D28: =[1]추출용DB!D21 -> H506*201*11*19 | E28: =[1]추출용DB!E21 -> 13300 | F28: =[1]추출용DB!G21 -> 3024.3
A29: =[1]추출용DB!B22 -> K.COLUMN | B29: =[1]추출용DB!C22 -> 9C002 | D29: =[1]추출용DB!D22 -> H506*201*11*19 | E29: =[1]추출용DB!E22 -> 12794 | F29: =[1]추출용DB!G22 -> 3301.8
A30: =[1]추출용DB!B31 -> K.COLUMN | B30: =[1]추출용DB!C31 -> 14C001 | D30: =[1]추출용DB!D31 -> H506*201*11*19 | E30: =[1]추출용DB!E31 -> 13300 | F30: =[1]추출용DB!G31 -> 3024.3
A31: =[1]추출용DB!B32 -> K.COLUMN | B31: =[1]추출용DB!C32 -> 14C002 | D31: =[1]추출용DB!D32 -> H506*201*11*19 | E31: =[1]추출용DB!E32 -> 12794 | F31: =[1]추출용DB!G32 -> 3332.9
A32: =[1]추출용DB!B29 -> K.COLUMN | B32: =[1]추출용DB!C29 -> 13C001 | D32: =[1]추출용DB!D29 -> H506*201*11*19 | E32: =[1]추출용DB!E29 -> 12800 | F32: =[1]추출용DB!G29 -> 3010.7
A33: =[1]추출용DB!B30 -> K.COLUMN | B33: =[1]추출용DB!C30 -> 13C002 | D33: =[1]추출용DB!D30 -> H506*201*11*19 | E33: =[1]추출용DB!E30 -> 12794 | F33: =[1]추출용DB!G30 -> 3365.4
A34: =[1]추출용DB!B39 -> K.COLUMN | B34: =[1]추출용DB!C39 -> 18C001 | D34: =[1]추출용DB!D39 -> H506*201*11*19 | E34: =[1]추출용DB!E39 -> 12800 | F34: =[1]추출용DB!G39 -> 2903.4
A35: =[1]추출용DB!B40 -> K.COLUMN | B35: =[1]추출용DB!C40 -> 18C002 | D35: =[1]추출용DB!D40 -> H506*201*11*19 | E35: =[1]추출용DB!E40 -> 11994 | F35: =[1]추출용DB!G40 -> 3151.3
A36: =[1]추출용DB!B37 -> T.COLUMN | B36: =[1]추출용DB!C37 -> 17TC001 | D36: =[1]추출용DB!D37 -> H450*200*9*14 | E36: =[1]추출용DB!E37 -> 14200 | F36: =[1]추출용DB!G37 -> 2361.3
A37: =[1]추출용DB!B38 -> T.COLUMN | B37: =[1]추출용DB!C38 -> 17TC002 | D37: =[1]추출용DB!D38 -> H450*200*9*14 | E37: =[1]추출용DB!E38 -> 12794 | F37: =[1]추출용DB!G38 -> 2454.4
A38: =[1]추출용DB!B35 -> K.COLUMN | B38: =[1]추출용DB!C35 -> 16C001 | D38: =[1]추출용DB!D35 -> H500*200*10*16 | E38: =[1]추출용DB!E35 -> 14200 | F38: =[1]추출용DB!G35 -> 2836
A39: =[1]추출용DB!B36 -> K.COLUMN | B39: =[1]추출용DB!C36 -> 16C002 | D39: =[1]추출용DB!D36 -> H500*200*10*16 | E39: =[1]추출용DB!E36 -> 12794 | F39: =[1]추출용DB!G36 -> 3098.6
A40: =[1]추출용DB!B33 -> T.COLUMN | B40: =[1]추출용DB!C33 -> 15TC001 | D40: =[1]추출용DB!D33 -> H450*200*9*14 | E40: =[1]추출용DB!E33 -> 14200 | F40: =[1]추출용DB!G33 -> 2433
...
